<robot
  name="aimibot">
  <link name="base_footprint"/>
    <joint name="base_joint" type="fixed">
      <origin xyz="0 0 0.0102" rpy="0 0 0" />
      <parent link="base_footprint"/>
      <child link="base_link" />
    </joint>
  <link
    name="base_link">
    <inertial>
      <origin
        xyz="0.0011466 0.08357 -0.00067389"
        rpy="0 0 0" />
      <mass
        value="6.6966" />
      <inertia
        ixx="0.14317"
        ixy="-0.00031972"
        ixz="0.00068273"
        iyy="0.14797"
        iyz="-0.00012584"
        izz="0.18653" />
    </inertial>
    <visual>
      <origin
        xyz="0 0 0"
        rpy="0 0 0" />
      <geometry>
        <mesh
          filename="package://aimibot_description/meshes/base_link.STL" />
      </geometry>
      <material
        name="">
        <color
          rgba="0.75294 0.75294 0.75294 1" />
      </material>
    </visual>
    <collision>
      <origin
        xyz="0 0 0"
        rpy="0 0 0" />
      <geometry>
        <mesh
          filename="package://aimibot_description/meshes/base_link.STL" />
      </geometry>
    </collision>
  </link>
  <link
    name="wheel_left_link">
    <inertial>
      <origin
        xyz="2.4427E-06 -2.4575E-05 -0.020357"
        rpy="0 0 0" />
      <mass
        value="0.26665" />
      <inertia
        ixx="0.0003764"
        ixy="3.0786E-10"
        ixz="-9.5991E-10"
        iyy="0.00037648"
        iyz="4.4037E-08"
        izz="0.00067934" />
    </inertial>
    <visual>
      <origin
        xyz="0 0 0"
        rpy="0 0 0" />
      <geometry>
        <mesh
          filename="package://aimibot_description/meshes/wheel_left_link.STL" />
      </geometry>
      <material
        name="">
        <color
          rgba="0.75294 0.75294 0.75294 1" />
      </material>
    </visual>
    <collision>
      <origin
        xyz="0 0 0"
        rpy="0 0 0" />
      <geometry>
        <mesh
          filename="package://aimibot_description/meshes/wheel_left_link.STL" />
      </geometry>
    </collision>
  </link>
  <joint
    name="wheel_left_joint"
    type="continuous">
    <origin
      xyz="0 -0.164485734157727 0.000420907718167048"
      rpy="1.5543789313971 -0.401173413748992 -3.13518119121522" />
    <parent
      link="base_link" />
    <child
      link="wheel_left_link" />
    <axis
      xyz="0 0 -1" />
  </joint>
  <link
    name="wheel_right_link">
    <inertial>
      <origin
        xyz="2.421E-06 -2.4578E-05 -0.02256"
        rpy="0 0 0" />
      <mass
        value="0.26665" />
      <inertia
        ixx="0.00037639"
        ixy="3.3764E-10"
        ixz="-1.0254E-09"
        iyy="0.00037648"
        iyz="4.4035E-08"
        izz="0.00067933" />
    </inertial>
    <visual>
      <origin
        xyz="0 0 0"
        rpy="0 0 0" />
      <geometry>
        <mesh
          filename="package://aimibot_description/meshes/wheel_right_link.STL" />
      </geometry>
      <material
        name="">
        <color
          rgba="0.75294 0.75294 0.75294 1" />
      </material>
    </visual>
    <collision>
      <origin
        xyz="0 0 0"
        rpy="0 0 0" />
      <geometry>
        <mesh
          filename="package://aimibot_description/meshes/wheel_right_link.STL" />
      </geometry>
    </collision>
  </link>
  <joint
    name="wheel_right_joint"
    type="continuous">
    <origin
      xyz="0 0.162282644955071 0.000454207317838345"
      rpy="1.48583093998881 -1.39175190584411 0.0836135299332929" />
    <parent
      link="base_link" />
    <child
      link="wheel_right_link" />
    <axis
      xyz="0 0 1" />
  </joint>
  <link
    name="laser_link">
    <inertial>
      <origin
        xyz="-0.0071364 0.028563 0.076176"
        rpy="0 0 0" />
      <mass
        value="0.043541" />
      <inertia
        ixx="2.3815E-05"
        ixy="2.7129E-06"
        ixz="3.3495E-07"
        iyy="3.9869E-05"
        iyz="-5.2368E-07"
        izz="3.0337E-05" />
    </inertial>
    <visual>
      <origin
        xyz="0 0 0"
        rpy="0 0 0" />
      <geometry>
        <mesh
          filename="package://aimibot_description/meshes/laser_link.STL" />
      </geometry>
      <material
        name="">
        <color
          rgba="0.75294 0.75294 0.75294 1" />
      </material>
    </visual>
    <collision>
      <origin
        xyz="0 0 0"
        rpy="0 0 0" />
      <geometry>
        <mesh
          filename="package://aimibot_description/meshes/laser_link.STL" />
      </geometry>
    </collision>
  </link>
  <joint
    name="laser_joint"
    type="fixed">
    <origin
      xyz="0.0060269 0.075 0.37143"
      rpy="1.5708 0 0" />
    <parent
      link="base_link" />
    <child
      link="laser_link" />
    <axis
      xyz="0 0 0" />
  </joint>
</robot>
